Workbook

Sheet Screen Status
A1: # | B1: Screen | C1: Endpoints | D1: Integrated | E1: New API added? | F1: Last updated | G1: Tour covers all options? | H1: Notes | J1: Summary | K1: Count
A2: 1 | B2: Overall Summary | C2: =COUNTIF(Endpoints!$A:$A,$B2) | D2: =COUNTIFS(Endpoints!$A:$A,$B2,Endpoints!$E:$E,"Integrated")+COUNTIFS(Endpoints!$A:$A,$B2,Endpoints!$E:$E,"Verified") | E2: =IF(C2=0,"No API",IF(D2=0,"No",IF(D2=C2,"Yes","Partial"))) | F2: =IFERROR(SUMPRODUCT(MAX((Endpoints!$A$2:$A$500=$B2)*Endpoints!$F$2:$F$500)),"") | G2: Yes | H2: DONE 2026-10-06: both endpoints switched to the new backend; tour covers the whole screen (17 steps, 2026-10-07). Next: one check against the real server. | J2: Screens fully on new API | K2: =COUNTIF($E$2:$E$24,"Yes")
A3: 2 | B3: Location Summary | C3: =COUNTIF(Endpoints!$A:$A,$B3) | D3: =COUNTIFS(Endpoints!$A:$A,$B3,Endpoints!$E:$E,"Integrated")+COUNTIFS(Endpoints!$A:$A,$B3,Endpoints!$E:$E,"Verified") | E3: =IF(C3=0,"No API",IF(D3=0,"No",IF(D3=C3,"Yes","Partial"))) | F3: =IFERROR(SUMPRODUCT(MAX((Endpoints!$A$2:$A$500=$B3)*Endpoints!$F$2:$F$500)),"") | G3: Yes | H3: DONE 2026-10-07: all 4 endpoints switched to the new backend and the tour covers every tab and modal (26 steps). Next: one check against the real server. | J3: Screens partly on new API | K3: =COUNTIF($E$2:$E$24,"Partial")
A4: 3 | B4: Location Details | C4: =COUNTIF(Endpoints!$A:$A,$B4) | D4: =COUNTIFS(Endpoints!$A:$A,$B4,Endpoints!$E:$E,"Integrated")+COUNTIFS(Endpoints!$A:$A,$B4,Endpoints!$E:$E,"Verified") | E4: =IF(C4=0,"No API",IF(D4=0,"No",IF(D4=C4,"Yes","Partial"))) | F4: =IFERROR(SUMPRODUCT(MAX((Endpoints!$A$2:$A$500=$B4)*Endpoints!$F$2:$F$500)),"") | G4: Yes | H4: DONE 2026-10-07: all 6 calls are on the new backend (4 own endpoints, including the Inventory-tab date popup, plus the 2 location-picker dropdowns shared with Location Summary); tour covers the whole screen (20 steps, 5 when no location is picked). Tell the backend team: inventoryData and inventoryDataByLocationByDate are on locationSummaryController; confirm previousMonths / previousYears. Next: one check against the real server. | J4: Screens not started | K4: =COUNTIF($E$2:$E$24,"No")
A5: 4 | B5: Location Insight | C5: =COUNTIF(Endpoints!$A:$A,$B5) | D5: =COUNTIFS(Endpoints!$A:$A,$B5,Endpoints!$E:$E,"Integrated")+COUNTIFS(Endpoints!$A:$A,$B5,Endpoints!$E:$E,"Verified") | E5: =IF(C5=0,"No API",IF(D5=0,"No",IF(D5=C5,"Yes","Partial"))) | F5: =IFERROR(SUMPRODUCT(MAX((Endpoints!$A$2:$A$500=$B5)*Endpoints!$F$2:$F$500)),"") | G5: Yes | H5: DONE 2026-10-07: all 3 calls are on the new backend (listOfLocationInsight on the new response shape, plus the 2 location-picker dropdowns shared with Location Summary); tour rebuilt to cover the picker, Refresh, headline figures and all four chart tabs (11 steps, 5 when no location is picked). Day-wise string format to be confirmed (see Endpoints). | J5: Screens with no API | K5: =COUNTIF($E$2:$E$24,"No API")
A6: 5 | B6: Daily PRJ | C6: =COUNTIF(Endpoints!$A:$A,$B6) | D6: =COUNTIFS(Endpoints!$A:$A,$B6,Endpoints!$E:$E,"Integrated")+COUNTIFS(Endpoints!$A:$A,$B6,Endpoints!$E:$E,"Verified") | E6: =IF(C6=0,"No API",IF(D6=0,"No",IF(D6=C6,"Yes","Partial"))) | F6: =IFERROR(SUMPRODUCT(MAX((Endpoints!$A$2:$A$500=$B6)*Endpoints!$F$2:$F$500)),"") | G6: Yes | H6: DONE 2026-10-08 (hold lifted): both calls (summary, and one location's detail) are on the new analysis-service dailyPRJ endpoint with the same params and response structure as before. Tour rebuilt to cover Refresh, search, Download Excel and its confirm dialog, Hide/Show table, the location table, then a location's picker, date search, month rollups, cumulative / PRJ-breakdown switches, day table and PRJ Target Summary (17 steps). Next: one check against the real server. | J6: Total endpoints | K6: =SUM($C$2:$C$24)
A7: 6 | B7: Consumption Analysis | C7: =COUNTIF(Endpoints!$A:$A,$B7) | D7: =COUNTIFS(Endpoints!$A:$A,$B7,Endpoints!$E:$E,"Integrated")+COUNTIFS(Endpoints!$A:$A,$B7,Endpoints!$E:$E,"Verified") | E7: =IF(C7=0,"No API",IF(D7=0,"No",IF(D7=C7,"Yes","Partial"))) | F7: =IFERROR(SUMPRODUCT(MAX((Endpoints!$A$2:$A$500=$B7)*Endpoints!$F$2:$F$500)),"") | G7: Yes | H7: DONE 2026-10-08 (hold lifted): all 8 calls (7 endpoints) are on the new analysis-service with the new {success, data} responses. The detail call's new lists (summaryList / srcTypeList / perMandayList) are mapped back to what the screen uses; the Excel download handles a file, a JSON error or a JSON file link and shows the backend's message if it refuses. Failures to load the filter lists are now shown in the filter dialog. Tour rebuilt to cover Refresh, search, Download Excel and its confirmation, the summary table, the Filters button, its dialog and Apply, Clear, the chart with its metric switch, tabs and drilled-in view, and the item table (up to 21 steps, 12 when the summary is empty). Tell the backend team: unit price, the per-manday map, the Excel response. Next: one check against the real server. | J7: Endpoints integrated | K7: =SUM($D$2:$D$24)
A8: 7 | B8: Stock on Hand | C8: =COUNTIF(Endpoints!$A:$A,$B8) | D8: =COUNTIFS(Endpoints!$A:$A,$B8,Endpoints!$E:$E,"Integrated")+COUNTIFS(Endpoints!$A:$A,$B8,Endpoints!$E:$E,"Verified") | E8: =IF(C8=0,"No API",IF(D8=0,"No",IF(D8=C8,"Yes","Partial"))) | F8: =IFERROR(SUMPRODUCT(MAX((Endpoints!$A$2:$A$500=$B8)*Endpoints!$F$2:$F$500)),"") | G8: Yes | H8: DONE 2026-10-08: all 6 calls (5 endpoints) are on the new analysis-service with the {success, data} responses. sohAnalysisLst now returns {summary, sohList}; mapped back to the rows and the days-holding threshold. The Excel download handles a file, a JSON error or a JSON file link and shows the backend's message if it refuses; location-list failures are now shown. Tour rebuilt: Refresh, summary search, Download All and its confirmation, the summary table, the location picker, Download Location, then the category chart, item category, item search and item table (up to 15 steps, 9 when the summary is empty). Tell the backend team: the overallDropDown controller name (assumed locationDetailsController), the Excel response, and that sohList rows carry locationId. Next: one check against the real server. | J8: Tours covering every option | K8: =COUNTIF($G$2:$G$24,"Yes")
A9: 8 | B9: Data Tracker Report | C9: =COUNTIF(Endpoints!$A:$A,$B9) | D9: =COUNTIFS(Endpoints!$A:$A,$B9,Endpoints!$E:$E,"Integrated")+COUNTIFS(Endpoints!$A:$A,$B9,Endpoints!$E:$E,"Verified") | E9: =IF(C9=0,"No API",IF(D9=0,"No",IF(D9=C9,"Yes","Partial"))) | F9: =IFERROR(SUMPRODUCT(MAX((Endpoints!$A$2:$A$500=$B9)*Endpoints!$F$2:$F$500)),"") | G9: Yes | H9: DONE 2026-10-08: the 1 call is on the new analysis-service (same call as old ELMS; the Excel link is in the same response). The response is read bare or inside the new envelope, and the link from download_url or downloadUrlPath. Tour rebuilt to cover Refresh, the summary line, the Yes/No legend, search, Download Excel (only when a link is returned) and the grid (8 steps). Tell the backend team: the swagger response is {} - please confirm the shape. Next: one check against the real server. | J9: Tours still to review | K9: =COUNTIF($G$2:$G$24,"No")
A10: 9 | B10: Target PRJ | C10: =COUNTIF(Endpoints!$A:$A,$B10) | D10: =COUNTIFS(Endpoints!$A:$A,$B10,Endpoints!$E:$E,"Integrated")+COUNTIFS(Endpoints!$A:$A,$B10,Endpoints!$E:$E,"Verified") | E10: =IF(C10=0,"No API",IF(D10=0,"No",IF(D10=C10,"Yes","Partial"))) | F10: =IFERROR(SUMPRODUCT(MAX((Endpoints!$A$2:$A$500=$B10)*Endpoints!$F$2:$F$500)),"") | G10: Yes | H10: DONE 2026-10-08: both calls are on the new overallSummary-service (locationInsightController) with the new {success, data} responses; a failed save now shows the backend's own message. Tour rebuilt to cover the month picker, Refresh, search, Download, unsaved markers, the location list, Update Target and the dialog (values, Reset, Update) - 12 steps, 8 when no location is listed. Tell the backend team: the extra fields on the save request. Next: one check against the real server. | J10: Endpoints to raise with backend | K10: =COUNTIF(Endpoints!$G:$G,"Yes")
A11: 10 | B11: Productivity | C11: =COUNTIF(Endpoints!$A:$A,$B11) | D11: =COUNTIFS(Endpoints!$A:$A,$B11,Endpoints!$E:$E,"Integrated")+COUNTIFS(Endpoints!$A:$A,$B11,Endpoints!$E:$E,"Verified") | E11: =IF(C11=0,"No API",IF(D11=0,"No",IF(D11=C11,"Yes","Partial"))) | F11: =IFERROR(SUMPRODUCT(MAX((Endpoints!$A$2:$A$500=$B11)*Endpoints!$F$2:$F$500)),"") | G11: Yes | H11: DONE 2026-10-08: both calls are on the new overallSummary-service (locationInsightController) with the new {success, data} responses; a failed save now shows the backend's own message. Tour rebuilt to cover the month picker, Refresh, search, the unsaved marker, Save and the table (8 steps; the unsaved step only shows once a value is edited). Tell the backend team: the extra fields on the save request. Next: one check against the real server.
A12: 11 | B12: Report | C12: =COUNTIF(Endpoints!$A:$A,$B12) | D12: =COUNTIFS(Endpoints!$A:$A,$B12,Endpoints!$E:$E,"Integrated")+COUNTIFS(Endpoints!$A:$A,$B12,Endpoints!$E:$E,"Verified") | E12: =IF(C12=0,"No API",IF(D12=0,"No",IF(D12=C12,"Yes","Partial"))) | F12: =IFERROR(SUMPRODUCT(MAX((Endpoints!$A$2:$A$500=$B12)*Endpoints!$F$2:$F$500)),"") | G12: Yes | H12: DONE 2026-10-07: the 1 call (35 reports through one path) matches the new backend's swagger path; the download link is read from download_url or the new envelope's downloadUrlPath. Tour rebuilt to cover Reset form, the report picker, the period, Generate, and (once a report has been generated) the result panel, Recent Generations and Clear history (10 steps; the last 3 are skipped until a run). Tell the backend team: confirm the other 34 report methods and the response shape. Next: one check against the real server.
A13: 12 | B13: Category Analysis | C13: =COUNTIF(Endpoints!$A:$A,$B13) | D13: =COUNTIFS(Endpoints!$A:$A,$B13,Endpoints!$E:$E,"Integrated")+COUNTIFS(Endpoints!$A:$A,$B13,Endpoints!$E:$E,"Verified") | E13: =IF(C13=0,"No API",IF(D13=0,"No",IF(D13=C13,"Yes","Partial"))) | F13: =IFERROR(SUMPRODUCT(MAX((Endpoints!$A$2:$A$500=$B13)*Endpoints!$F$2:$F$500)),"") | G13: Yes | H13: DONE 2026-10-07: all 6 calls are on the new item-analysis-summary-service (5 on categoryAnalysisController incl. the dropdowns, 1 on itemIngredientAnalysisController) with the new {success, data} responses; tour rebuilt to cover the picker, Refresh, source type, date, Fetch/Clear, POB, chart, search and the group, category and item levels (17 steps, 4 when no location is picked). Tell the backend team: listOfItemIngredientAnalysis fromDate/toDate/periodStr. Next: one check against the real server.
A14: 13 | B14: Item Analysis | C14: =COUNTIF(Endpoints!$A:$A,$B14) | D14: =COUNTIFS(Endpoints!$A:$A,$B14,Endpoints!$E:$E,"Integrated")+COUNTIFS(Endpoints!$A:$A,$B14,Endpoints!$E:$E,"Verified") | E14: =IF(C14=0,"No API",IF(D14=0,"No",IF(D14=C14,"Yes","Partial"))) | F14: =IFERROR(SUMPRODUCT(MAX((Endpoints!$A$2:$A$500=$B14)*Endpoints!$F$2:$F$500)),"") | G14: Yes | H14: DONE 2026-10-08: all 6 calls are on the new item-analysis-summary-service with the new {success, data} responses - 4 on its own itemIngredientAnalysisController (2 location dropdowns incl. index 0, the location-by-category list, and the item analysis itself), the category list reused from Item Breakup and the SRC type list reused from Category Analysis. Failures to load the filter lists are now shown on the page. Tour rebuilt to cover the location picker, Refresh, Source Type, Category, Date, Fetch / Clear, the chart and its drilled-in view with Back, search and the table (14 steps, 4 when no location is chosen). Tell the backend team: categoryId in categoryList vs itemList. Next: one check against the real server.
A15: 14 | B15: Item Breakup | C15: =COUNTIF(Endpoints!$A:$A,$B15) | D15: =COUNTIFS(Endpoints!$A:$A,$B15,Endpoints!$E:$E,"Integrated")+COUNTIFS(Endpoints!$A:$A,$B15,Endpoints!$E:$E,"Verified") | E15: =IF(C15=0,"No API",IF(D15=0,"No",IF(D15=C15,"Yes","Partial"))) | F15: =IFERROR(SUMPRODUCT(MAX((Endpoints!$A$2:$A$500=$B15)*Endpoints!$F$2:$F$500)),"") | G15: Yes | H15: DONE 2026-10-07: all 5 calls are on the new item-analysis-summary-service (itemBreakupController) with the new {success, data} responses; tour rebuilt to cover the Filters modal, clear, the 3/6/9/12 months switch, search and the table (8 steps, 4 when no filter is applied). Tell the backend team: the previousQt6 spelling and the dropped type field on listOfItemBreakup. Next: one check against the real server.
A16: 15 | B16: WasteCost Analysis | C16: =COUNTIF(Endpoints!$A:$A,$B16) | D16: =COUNTIFS(Endpoints!$A:$A,$B16,Endpoints!$E:$E,"Integrated")+COUNTIFS(Endpoints!$A:$A,$B16,Endpoints!$E:$E,"Verified") | E16: =IF(C16=0,"No API",IF(D16=0,"No",IF(D16=C16,"Yes","Partial"))) | F16: =IFERROR(SUMPRODUCT(MAX((Endpoints!$A$2:$A$500=$B16)*Endpoints!$F$2:$F$500)),"") | G16: No | H16: ON HOLD (2026-10-08, by the backend team).
A17: 16 | B17: User Master | C17: =COUNTIF(Endpoints!$A:$A,$B17) | D17: =COUNTIFS(Endpoints!$A:$A,$B17,Endpoints!$E:$E,"Integrated")+COUNTIFS(Endpoints!$A:$A,$B17,Endpoints!$E:$E,"Verified") | E17: =IF(C17=0,"No API",IF(D17=0,"No",IF(D17=C17,"Yes","Partial"))) | F17: =IFERROR(SUMPRODUCT(MAX((Endpoints!$A$2:$A$500=$B17)*Endpoints!$F$2:$F$500)),"") | G17: Yes | H17: DONE 2026-10-08: all 5 calls use the new {success, message, data} responses (same login-credential-service and paths as the old app); a refused create / edit / status / password reset now shows the backend's own message in the dialog. Tour rebuilt to cover Refresh, Add User, search, the table, the Modify and Reset buttons and all three dialogs (Add User with its password and Create button, Modify User with Account Status and Save, Reset Password) - 16 steps, 9 when no user is listed. Tell the backend team: do not return password in the user list. Next: one check against the real server.
A18: 17 | B18: Location Rights | C18: =COUNTIF(Endpoints!$A:$A,$B18) | D18: =COUNTIFS(Endpoints!$A:$A,$B18,Endpoints!$E:$E,"Integrated")+COUNTIFS(Endpoints!$A:$A,$B18,Endpoints!$E:$E,"Verified") | E18: =IF(C18=0,"No API",IF(D18=0,"No",IF(D18=C18,"Yes","Partial"))) | F18: =IFERROR(SUMPRODUCT(MAX((Endpoints!$A$2:$A$500=$B18)*Endpoints!$F$2:$F$500)),"") | G18: Yes | H18: DONE 2026-10-08: all 3 calls use the new {success, message, data} responses (same login-credential-service and paths as the old app); failures to load the users or a user's locations are now shown on the page, and a refused save shows the backend's own message. Tour rebuilt to cover Reset, Save Rights, the user picker, Refresh, the selected count, search, select-all, the row checkboxes and Allowed / Restricted pills, and the save confirmation (11 steps, 5 when no user is listed). Tell the backend team: which name fields the location rows fill. Next: one check against the real server.
A19: 18 | B19: Screen Rights | C19: =COUNTIF(Endpoints!$A:$A,$B19) | D19: =COUNTIFS(Endpoints!$A:$A,$B19,Endpoints!$E:$E,"Integrated")+COUNTIFS(Endpoints!$A:$A,$B19,Endpoints!$E:$E,"Verified") | E19: =IF(C19=0,"No API",IF(D19=0,"No",IF(D19=C19,"Yes","Partial"))) | F19: =IFERROR(SUMPRODUCT(MAX((Endpoints!$A$2:$A$500=$B19)*Endpoints!$F$2:$F$500)),"") | G19: n/a | H19: New screen (the old app had none). The page is a placeholder in the sidebar until the backend provides screen-rights endpoints (load a user's rights, save).
A20: 19 | B20: User Log | C20: =COUNTIF(Endpoints!$A:$A,$B20) | D20: =COUNTIFS(Endpoints!$A:$A,$B20,Endpoints!$E:$E,"Integrated")+COUNTIFS(Endpoints!$A:$A,$B20,Endpoints!$E:$E,"Verified") | E20: =IF(C20=0,"No API",IF(D20=0,"No",IF(D20=C20,"Yes","Partial"))) | F20: =IFERROR(SUMPRODUCT(MAX((Endpoints!$A$2:$A$500=$B20)*Endpoints!$F$2:$F$500)),"") | G20: Yes | H20: DONE 2026-10-08: both calls are on the same login-credential-service paths as the old app; the log list reads the new {success, message, data} response, and a failed load is now shown on the page. The Excel export handles a file, a JSON error (its message is shown instead of saving a broken .xlsx) and a JSON file link, since its response structure is not documented. Tour rebuilt to cover Reset, Refresh, Export, the four period pickers (Day, Week, Month, Year), search and the table (12 steps). Tell the backend team: the Excel response and the day format. Next: one check against the real server.
A21: 20 | B21: Month Closing | C21: =COUNTIF(Endpoints!$A:$A,$B21) | D21: =COUNTIFS(Endpoints!$A:$A,$B21,Endpoints!$E:$E,"Integrated")+COUNTIFS(Endpoints!$A:$A,$B21,Endpoints!$E:$E,"Verified") | E21: =IF(C21=0,"No API",IF(D21=0,"No",IF(D21=C21,"Yes","Partial"))) | F21: =IFERROR(SUMPRODUCT(MAX((Endpoints!$A$2:$A$500=$B21)*Endpoints!$F$2:$F$500)),"") | G21: No | H21: ON HOLD (2026-10-08, by the backend team). NOT MIGRATED: 1 call (close the month) in both apps, but not the same endpoint. Old ELMS calls GET .../consolidated-python-report-service/pythonReportController/monthClosing through the api-gateway; the new app calls POST http://103.73.189.202:5000/pull/month-closing directly (separate host, plain http). See the Endpoints and Old vs New APIs sheets. Waiting for a decision and the new backend API. Tour not reviewed yet.
A22: 21 | B22: General Settings | C22: =COUNTIF(Endpoints!$A:$A,$B22) | D22: =COUNTIFS(Endpoints!$A:$A,$B22,Endpoints!$E:$E,"Integrated")+COUNTIFS(Endpoints!$A:$A,$B22,Endpoints!$E:$E,"Verified") | E22: =IF(C22=0,"No API",IF(D22=0,"No",IF(D22=C22,"Yes","Partial"))) | F22: =IFERROR(SUMPRODUCT(MAX((Endpoints!$A$2:$A$500=$B22)*Endpoints!$F$2:$F$500)),"") | G22: No | H22: Number-format settings are stored in the browser only. No backend endpoint exists.
... A24: 23 | B24: Change Password (profile menu) | C24: =COUNTIF(Endpoints!$A:$A,$B24) | D24: =COUNTIFS(Endpoints!$A:$A,$B24,Endpoints!$E:$E,"Integrated")+COUNTIFS(Endpoints!$A:$A,$B24,Endpoints!$E:$E,"Verified") | E24: =IF(C24=0,"No API",IF(D24=0,"No",IF(D24=C24,"Yes","Partial"))) | F24: =IFERROR(SUMPRODUCT(MAX((Endpoints!$A$2:$A$500=$B24)*Endpoints!$F$2:$F$500)),"") | G24: n/a | H24: Opened from the header profile menu, not the sidebar. Its one call (userPasswordUpdateByAdmin) now reads the new {success, message, data} response; same endpoint as User Master's admin reset.

Sheet Old vs New APIs
A1: Old ELMS APIs vs the new app - screens checked so far
A2: One count = one call the screen makes. A call used two ways (e.g. with and without locationId, or index 0 vs 1-3) is listed as its own row but is one endpoint path.
A4: Screen | B4: API calls in old ELMS | C4: API calls used in new AGS ELMS | D4: Replaced with new backend | E4: OLD API kept (to migrate) | F4: Not added (never called) | G4: Still on old backend (pending)
A5: Overall Summary | B5: =COUNTIF($A$26:$A$91,A5) | C5: =COUNTIFS($A$26:$A$91,A5,$E$26:$E$91,"<>Not added - never called in old app") | D5: =COUNTIFS($A$26:$A$91,A5,$E$26:$E$91,"Replaced with new backend") | E5: =COUNTIFS($A$26:$A$91,A5,$E$26:$E$91,"OLD API kept (to migrate)") | F5: =COUNTIFS($A$26:$A$91,A5,$E$26:$E$91,"Not added - never called in old app") | G5: =COUNTIFS($A$26:$A$91,A5,$E$26:$E$91,"Still on old backend - waiting for new API")
A6: Location Summary | B6: =COUNTIF($A$26:$A$91,A6) | C6: =COUNTIFS($A$26:$A$91,A6,$E$26:$E$91,"<>Not added - never called in old app") | D6: =COUNTIFS($A$26:$A$91,A6,$E$26:$E$91,"Replaced with new backend") | E6: =COUNTIFS($A$26:$A$91,A6,$E$26:$E$91,"OLD API kept (to migrate)") | F6: =COUNTIFS($A$26:$A$91,A6,$E$26:$E$91,"Not added - never called in old app") | G6: =COUNTIFS($A$26:$A$91,A6,$E$26:$E$91,"Still on old backend - waiting for new API")
A7: Location Details | B7: =COUNTIF($A$26:$A$91,A7) | C7: =COUNTIFS($A$26:$A$91,A7,$E$26:$E$91,"<>Not added - never called in old app") | D7: =COUNTIFS($A$26:$A$91,A7,$E$26:$E$91,"Replaced with new backend") | E7: =COUNTIFS($A$26:$A$91,A7,$E$26:$E$91,"OLD API kept (to migrate)") | F7: =COUNTIFS($A$26:$A$91,A7,$E$26:$E$91,"Not added - never called in old app") | G7: =COUNTIFS($A$26:$A$91,A7,$E$26:$E$91,"Still on old backend - waiting for new API")
A8: Location Insight | B8: =COUNTIF($A$26:$A$91,A8) | C8: =COUNTIFS($A$26:$A$91,A8,$E$26:$E$91,"<>Not added - never called in old app") | D8: =COUNTIFS($A$26:$A$91,A8,$E$26:$E$91,"Replaced with new backend") | E8: =COUNTIFS($A$26:$A$91,A8,$E$26:$E$91,"OLD API kept (to migrate)") | F8: =COUNTIFS($A$26:$A$91,A8,$E$26:$E$91,"Not added - never called in old app") | G8: =COUNTIFS($A$26:$A$91,A8,$E$26:$E$91,"Still on old backend - waiting for new API")
A9: Daily PRJ | B9: =COUNTIF($A$26:$A$91,A9) | C9: =COUNTIFS($A$26:$A$91,A9,$E$26:$E$91,"<>Not added - never called in old app") | D9: =COUNTIFS($A$26:$A$91,A9,$E$26:$E$91,"Replaced with new backend") | E9: =COUNTIFS($A$26:$A$91,A9,$E$26:$E$91,"OLD API kept (to migrate)") | F9: =COUNTIFS($A$26:$A$91,A9,$E$26:$E$91,"Not added - never called in old app") | G9: =COUNTIFS($A$26:$A$91,A9,$E$26:$E$91,"Still on old backend - waiting for new API")
A10: Consumption Analysis | B10: =COUNTIF($A$26:$A$91,A10) | C10: =COUNTIFS($A$26:$A$91,A10,$E$26:$E$91,"<>Not added - never called in old app") | D10: =COUNTIFS($A$26:$A$91,A10,$E$26:$E$91,"Replaced with new backend") | E10: =COUNTIFS($A$26:$A$91,A10,$E$26:$E$91,"OLD API kept (to migrate)") | F10: =COUNTIFS($A$26:$A$91,A10,$E$26:$E$91,"Not added - never called in old app") | G10: =COUNTIFS($A$26:$A$91,A10,$E$26:$E$91,"Still on old backend - waiting for new API")
A11: Category Analysis | B11: =COUNTIF($A$26:$A$91,A11) | C11: =COUNTIFS($A$26:$A$91,A11,$E$26:$E$91,"<>Not added - never called in old app") | D11: =COUNTIFS($A$26:$A$91,A11,$E$26:$E$91,"Replaced with new backend") | E11: =COUNTIFS($A$26:$A$91,A11,$E$26:$E$91,"OLD API kept (to migrate)") | F11: =COUNTIFS($A$26:$A$91,A11,$E$26:$E$91,"Not added - never called in old app") | G11: =COUNTIFS($A$26:$A$91,A11,$E$26:$E$91,"Still on old backend - waiting for new API")
A12: Item Breakup | B12: =COUNTIF($A$26:$A$91,A12) | C12: =COUNTIFS($A$26:$A$91,A12,$E$26:$E$91,"<>Not added - never called in old app") | D12: =COUNTIFS($A$26:$A$91,A12,$E$26:$E$91,"Replaced with new backend") | E12: =COUNTIFS($A$26:$A$91,A12,$E$26:$E$91,"OLD API kept (to migrate)") | F12: =COUNTIFS($A$26:$A$91,A12,$E$26:$E$91,"Not added - never called in old app") | G12: =COUNTIFS($A$26:$A$91,A12,$E$26:$E$91,"Still on old backend - waiting for new API")
A13: Report | B13: =COUNTIF($A$26:$A$91,A13) | C13: =COUNTIFS($A$26:$A$91,A13,$E$26:$E$91,"<>Not added - never called in old app") | D13: =COUNTIFS($A$26:$A$91,A13,$E$26:$E$91,"Replaced with new backend") | E13: =COUNTIFS($A$26:$A$91,A13,$E$26:$E$91,"OLD API kept (to migrate)") | F13: =COUNTIFS($A$26:$A$91,A13,$E$26:$E$91,"Not added - never called in old app") | G13: =COUNTIFS($A$26:$A$91,A13,$E$26:$E$91,"Still on old backend - waiting for new API")
A14: Data Tracker Report | B14: =COUNTIF($A$26:$A$91,A14) | C14: =COUNTIFS($A$26:$A$91,A14,$E$26:$E$91,"<>Not added - never called in old app") | D14: =COUNTIFS($A$26:$A$91,A14,$E$26:$E$91,"Replaced with new backend") | E14: =COUNTIFS($A$26:$A$91,A14,$E$26:$E$91,"OLD API kept (to migrate)") | F14: =COUNTIFS($A$26:$A$91,A14,$E$26:$E$91,"Not added - never called in old app") | G14: =COUNTIFS($A$26:$A$91,A14,$E$26:$E$91,"Still on old backend - waiting for new API")
A15: Stock on Hand | B15: =COUNTIF($A$26:$A$91,A15) | C15: =COUNTIFS($A$26:$A$91,A15,$E$26:$E$91,"<>Not added - never called in old app") | D15: =COUNTIFS($A$26:$A$91,A15,$E$26:$E$91,"Replaced with new backend") | E15: =COUNTIFS($A$26:$A$91,A15,$E$26:$E$91,"OLD API kept (to migrate)") | F15: =COUNTIFS($A$26:$A$91,A15,$E$26:$E$91,"Not added - never called in old app") | G15: =COUNTIFS($A$26:$A$91,A15,$E$26:$E$91,"Still on old backend - waiting for new API")
A16: Target PRJ | B16: =COUNTIF($A$26:$A$91,A16) | C16: =COUNTIFS($A$26:$A$91,A16,$E$26:$E$91,"<>Not added - never called in old app") | D16: =COUNTIFS($A$26:$A$91,A16,$E$26:$E$91,"Replaced with new backend") | E16: =COUNTIFS($A$26:$A$91,A16,$E$26:$E$91,"OLD API kept (to migrate)") | F16: =COUNTIFS($A$26:$A$91,A16,$E$26:$E$91,"Not added - never called in old app") | G16: =COUNTIFS($A$26:$A$91,A16,$E$26:$E$91,"Still on old backend - waiting for new API")
... A22: Item Analysis | B22: =COUNTIF($A$26:$A$91,A22) | C22: =COUNTIFS($A$26:$A$91,A22,$E$26:$E$91,"<>Not added - never called in old app") | D22: =COUNTIFS($A$26:$A$91,A22,$E$26:$E$91,"Replaced with new backend") | E22: =COUNTIFS($A$26:$A$91,A22,$E$26:$E$91,"OLD API kept (to migrate)") | F22: =COUNTIFS($A$26:$A$91,A22,$E$26:$E$91,"Not added - never called in old app") | G22: =COUNTIFS($A$26:$A$91,A22,$E$26:$E$91,"Still on old backend - waiting for new API")
A23: Total | B23: =SUM(B5:B22) | C23: =SUM(C5:C22) | D23: =SUM(D5:D22) | E23: =SUM(E5:E22) | F23: =SUM(F5:F22) | G23: =SUM(G5:G22)
A24: Every old API call, one by one
A25: Screen | B25: Method | C25: Old ELMS endpoint | D25: New endpoint | E25: Result | F25: Notes
A26: Overall Summary | B26: GET | C26: /lms-dashboard-watch-service/lmsDashBoardController/listOfLmsDashBorard/{date}/{userType}/{userId} | D26: /overallSummary-service/lmsDashBoardController/listOfLmsDashBorard/{date}/{userType}/{userId} | E26: Replaced with new backend
A27: Overall Summary | B27: POST | C27: /lms-dashboard-watch-service/lmsDashBoardController/categoryWiseData | D27: /overallSummary-service/lmsDashBoardController/categoryWiseData | E27: Replaced with new backend
A28: Location Summary | B28: POST | C28: /location-summary-service/locationSummaryController/listOfLocationSummary | D28: /overallSummary-service/locationSummaryController/listOfLocationSummary | E28: Replaced with new backend
A29: Location Summary | B29: GET | C29: /location-summary-service/locationSummaryController/overallDropDown/{apiIndex}/{date}/{userType}/{userId} | D29: /overallSummary-service/locationSummaryController/overallDropDown/{type}/{date}/{userType}/{userId} | E29: Replaced with new backend
A30: Location Summary | B30: GET | C30: /location-summary-service/locationSummaryController/dropDownByNameBased/{apiIndex}/{category}/{date}/{userType}/{userId} | D30: /overallSummary-service/locationSummaryController/dropDownByNameBased/{type}/{typeName}/{date}/{userType}/{userId} | E30: Replaced with new backend
A31: Location Summary | B31: GET | C31: /location-summary-service/locationSummaryController/inventoryDataByLocation/{date}/{locationId} | D31: /overallSummary-service/locationSummaryController/inventoryDataByLocation/{period}/{locationId} | E31: Replaced with new backend
A32: Location Details | B32: POST | C32: /location-details-service/locationDetailsController/listOfLocationDetails | D32: /overallSummary-service/locationDetailsController/listOfLocationDetails | E32: Replaced with new backend
A33: Location Details | B33: GET | C33: /location-details-service/locationDetailsController/srcTypeDropDown/{date}/{locationId}/{userType}/{userId} | D33: /overallSummary-service/locationDetailsController/srcTypeDropDown/{period}/{locationId}/{userType}/{userId} | E33: Replaced with new backend
A34: Location Details | B34: GET | C34: /location-summary-service/locationSummaryController/inventoryData/{date}/{locationId} | D34: /overallSummary-service/locationSummaryController/inventoryData/{period}/{locationId} | E34: Replaced with new backend
A35: Location Details | B35: GET | C35: /location-details-service/locationDetailsController/overallDropDown/{apiIndex}/{date}/{userType}/{userId} | D35: /overallSummary-service/locationSummaryController/overallDropDown/... (shared location picker) | E35: Replaced with new backend | F35: The picker reuses Location Summary's dropdown calls.
A36: Location Details | B36: GET | C36: /location-details-service/locationDetailsController/dropDownByNameBased/{apiIndex}/{category}/{date}/{userType}/{userId} | D36: /overallSummary-service/locationSummaryController/dropDownByNameBased/... (shared location picker) | E36: Replaced with new backend | F36: The picker reuses Location Summary's dropdown calls.
A37: Location Details | B37: GET | C37: /location-summary-service/locationSummaryController/inventoryDataByLocationByDate/{date}/{locationId}/{inventoryDate} | D37: /overallSummary-service/locationSummaryController/inventoryDataByLocationByDate/{period}/{locationId}/{date} | E37: Replaced with new backend | F37: Date popup on the Inventory tab. Added after the old-API stage; now on the new backend.
A38: Location Details | B38: GET | C38: /location-summary-service/locationSummaryController/inventoryList/{locationId}/{date} | D38: (none) | E38: Not added - never called in old app | F38: Defined in the old LmsDetails code but never called and no popup used it (dead code).
A39: Location Insight | B39: POST | C39: /location-insight-service/locationInsightController/listOfLocationInsight | D39: /overallSummary-service/locationInsightController/listOfLocationInsight | E39: Replaced with new backend
A40: Location Insight | B40: GET | C40: /location-insight-service/locationInsightController/overallDropDown/{apiIndex}/{date}/{userType}/{userId} | D40: /overallSummary-service/locationSummaryController/overallDropDown/... (shared location picker) | E40: Replaced with new backend | F40: The picker reuses Location Summary's dropdown calls.
A41: Location Insight | B41: GET | C41: /location-insight-service/locationInsightController/dropDownByNameBased/{apiIndex}/{category}/{date}/{userType}/{userId} | D41: /overallSummary-service/locationSummaryController/dropDownByNameBased/... (shared location picker) | E41: Replaced with new backend | F41: The picker reuses Location Summary's dropdown calls.
A42: Daily PRJ | B42: GET | C42: /consolidated-python-report-service/pythonReportController/dailyPRJ?period&userType&userFk (summary: every location's month row) | D42: /analysis-service/pythonReportController/dailyPRJ?period&userType&userFk | E42: Replaced with new backend | F42: Same endpoint as the other Daily PRJ row, now on analysis-service. Called without locationId for every location's month summary. Response structure unchanged.
A43: Daily PRJ | B43: GET | C43: /consolidated-python-report-service/pythonReportController/dailyPRJ?period&locationId&userType&userFk (one location, day by day) | D43: /analysis-service/pythonReportController/dailyPRJ?period&locationId&userType&userFk | E43: Replaced with new backend | F43: Same endpoint as the other Daily PRJ row, now on analysis-service. Called with locationId for one location's day-by-day detail. Response structure unchanged.
A44: Consumption Analysis | B44: GET | C44: /item-ingredient-analysis-service/itemIngredientAnalysisController/categoryDropDown | D44: /analysis-service/itemIngredientAnalysisController/categoryDropDown | E44: Replaced with new backend | F44: Moved to analysis-service, in the {success, data} envelope.
A45: Consumption Analysis | B45: GET | C45: /item-ingredient-analysis-service/itemIngredientAnalysisController/srcTypeDropDown/{date}/{locationId} | D45: /analysis-service/itemIngredientAnalysisController/srcTypeDropDown/{period}/{location} | E45: Replaced with new backend | F45: Moved to analysis-service, in the {success, data} envelope.
A46: Consumption Analysis | B46: GET | C46: /location-details-service/locationDetailsController/overallDropDown/{idx}/{date}/{userType}/{userId} | D46: /analysis-service/locationDetailsController/overallDropDown/{type}/{date}/{userType}/{userId} | E46: Replaced with new backend | F46: Moved to analysis-service, in the {success, data} envelope.
...

Sheet Endpoints
A1: Screen | B1: Method | C1: Old endpoint | D1: New endpoint | E1: Status | F1: Date integrated | G1: Tell backend team? | H1: Notes | I1: Old API still used? (to migrate)
A2: Overall Summary | B2: GET | C2: /lms-dashboard-watch-service/lmsDashBoardController/listOfLmsDashBorard/{date}/{userType}/{userId} | D2: /overallSummary-service/lmsDashBoardController/listOfLmsDashBorard/{date}/{userType}/{userId} | E2: Integrated | F2: 46301 | H2: Response is now {success, message, data:{summary, contractList, segmentList, operManagerList}}; mapped in api.ts. Service prefix was not given by the backend - assumed overallSummary-service. Needs a live check.
A3: Overall Summary | B3: POST | C3: /lms-dashboard-watch-service/lmsDashBoardController/categoryWiseData | D3: /overallSummary-service/lmsDashBoardController/categoryWiseData | E3: Integrated | F3: 46301 | H3: Body {category, month, year}. Response {success, message, data:[...]}.
A4: Location Summary | B4: POST | C4: /location-summary-service/locationSummaryController/listOfLocationSummary | D4: /overallSummary-service/locationSummaryController/listOfLocationSummary | E4: Integrated | F4: 46302 | H4: Service switched to overallSummary-service. Response is now {success, message, data:{summary, locationSummaryList, monthComparisonGraphList, dailyPrjList}}; mapped back in api.ts so the five tabs are unchanged. Request userId is now a number.
A5: Location Summary | B5: GET | C5: /location-summary-service/locationSummaryController/overallDropDown/{apiIndex}/{date}/{userType}/{userId} | D5: /overallSummary-service/locationSummaryController/overallDropDown/{type}/{date}/{userType}/{userId} | E5: Integrated | F5: 46302 | H5: Service switched to overallSummary-service. Response is {success, data:[...]}. A location may arrive as id/name or locationId/locationName; both are read. type 0 = all locations, 1-3 = category lists.
A6: Location Summary | B6: GET | C6: /location-summary-service/locationSummaryController/dropDownByNameBased/{apiIndex}/{category}/{date}/{userType}/{userId} | D6: /overallSummary-service/locationSummaryController/dropDownByNameBased/{type}/{typeName}/{date}/{userType}/{userId} | E6: Integrated | F6: 46302 | H6: Service switched to overallSummary-service. Response is {success, data:[...]}; the category is URL-encoded.
A7: Location Summary | B7: GET | C7: /location-summary-service/locationSummaryController/inventoryDataByLocation/{date}/{locationId} | D7: /overallSummary-service/locationSummaryController/inventoryDataByLocation/{period}/{locationId} | E7: Integrated | F7: 46302 | H7: Service switched to overallSummary-service. Response is {success, data:[...]}; period is the DD-MM-YYYY reporting date.
A8: Location Details | B8: POST | C8: /location-details-service/locationDetailsController/listOfLocationDetails | D8: /overallSummary-service/locationDetailsController/listOfLocationDetails | E8: Integrated | F8: 46302 | G8: Yes | H8: Service switched to overallSummary-service. Response is {success, message, data:{summary, srcDataList, consumptionDataList, splitPrjList, consumptionComparisonList}}; mapped back in api.ts so the five tabs are unchanged. Request: the old filter + yearList pair is gone (Consumption Compare now sends previousMonths / previousYears). TELL BACKEND TEAM: confirm those two lists hold only the comparison months, not the base month.
A9: Location Details | B9: GET | C9: /location-details-service/locationDetailsController/srcTypeDropDown/{date}/{locationId}/{userType}/{userId} | D9: /overallSummary-service/locationDetailsController/srcTypeDropDown/{period}/{locationId}/{userType}/{userId} | E9: Integrated | F9: 46302 | H9: Service switched to overallSummary-service. Response is {success, data:[...]}; the SRC type is read from name (code / id as fallbacks).
A10: Location Details | B10: GET | C10: /location-summary-service/locationSummaryController/inventoryData/{date}/{locationId} | D10: /overallSummary-service/locationSummaryController/inventoryData/{period}/{locationId} | E10: Integrated | F10: 46302 | G10: Yes | H10: TELL BACKEND TEAM: this call is on locationSummaryController, but the other two Location Details calls are on locationDetailsController. Confirm that is intended or whether it will move. Response is {success, data:[...]} and is mapped; the Inventory tab and the DIO trend chart read it.
A11: Location Details | B11: GET | C11: /location-summary-service/locationSummaryController/inventoryDataByLocationByDate/{date}/{locationId}/{inventoryDate} | D11: /overallSummary-service/locationSummaryController/inventoryDataByLocationByDate/{period}/{locationId}/{date} | E11: Integrated | F11: 46302 | H11: Migrated from the old location-summary-service (was an old API kept on purpose). Response is {success, data:[...]}; only category, itemId, itemName, packageId, closingQty and closingValue are read. Served by locationSummaryController like inventoryData. Opened by clicking a date on the Inventory tab; reuses the Location Summary inventory modal.
A12: Location Details | B12: GET | C12: /location-details-service/locationDetailsController/overallDropDown/{apiIndex}/{date}/{userType}/{userId} | D12: /overallSummary-service/locationSummaryController/overallDropDown/{type}/{date}/{userType}/{userId} (shared location picker) | E12: Integrated | F12: 46302 | H12: Same new endpoint as the Location Summary row of that name: the shared location picker (LocationPickerModal) calls Location Summary's dropdown functions, so this call already runs on the new backend.
A13: Location Details | B13: GET | C13: /location-details-service/locationDetailsController/dropDownByNameBased/{apiIndex}/{category}/{date}/{userType}/{userId} | D13: /overallSummary-service/locationSummaryController/dropDownByNameBased/{type}/{typeName}/{date}/{userType}/{userId} (shared location picker) | E13: Integrated | F13: 46302 | H13: Same new endpoint as the Location Summary row of that name: the shared location picker (LocationPickerModal) calls Location Summary's dropdown functions, so this call already runs on the new backend.
A14: Location Insight | B14: POST | C14: /location-insight-service/locationInsightController/listOfLocationInsight | D14: /overallSummary-service/locationInsightController/listOfLocationInsight | E14: Integrated | F14: 46302 | G14: Yes | H14: TELL BACKEND TEAM: response is now {success, message, data:{summary, dayWiseMandayList, dayWiseCumulativeDailyCostList, dayWiseConsumptionDataList}}; summary holds the figures and the date-keyed splitPrjList. Swagger types the three dayWise lists as string[] with no format, so they are parsed as 'DD-MM-YYYY: value' (the old app format) - please confirm. Request still sends only dateString, month, year, locationId.
A15: Location Insight | B15: GET | C15: /location-insight-service/locationInsightController/overallDropDown/{apiIndex}/{date}/{userType}/{userId} | D15: /overallSummary-service/locationSummaryController/overallDropDown/{type}/{date}/{userType}/{userId} (shared location picker) | E15: Integrated | F15: 46302 | H15: Same new endpoint as the Location Summary row of that name: the shared location picker (LocationPickerModal) calls Location Summary's dropdown functions, so this call already runs on the new backend.
A16: Location Insight | B16: GET | C16: /location-insight-service/locationInsightController/dropDownByNameBased/{apiIndex}/{category}/{date}/{userType}/{userId} | D16: /overallSummary-service/locationSummaryController/dropDownByNameBased/{type}/{typeName}/{date}/{userType}/{userId} (shared location picker) | E16: Integrated | F16: 46302 | H16: Same new endpoint as the Location Summary row of that name: the shared location picker (LocationPickerModal) calls Location Summary's dropdown functions, so this call already runs on the new backend.
A17: Daily PRJ | B17: GET | C17: /consolidated-python-report-service/pythonReportController/dailyPRJ?period&userType&userFk | D17: /analysis-service/pythonReportController/dailyPRJ?period&userType&userFk | E17: Integrated | F17: 46303 | H17: Summary: every location's month row (no locationId). Moved from consolidated-python-report-service to analysis-service. Params: period (YYYY-MM-01), userFk, userType, and the optional locationId. Response structure unchanged (read bare, or inside {success, message, data}; the file link from download_url or downloadUrlPath). The swagger path was written with a double slash (analysis-service//pythonReportController); the frontend uses a single slash.
A18: Daily PRJ | B18: GET | C18: /consolidated-python-report-service/pythonReportController/dailyPRJ?period&locationId&userType&userFk | D18: /analysis-service/pythonReportController/dailyPRJ?period&locationId&userType&userFk | E18: Integrated | F18: 46303 | H18: One location, day by day (same path as the summary row with locationId added). Moved from consolidated-python-report-service to analysis-service. Params: period (YYYY-MM-01), userFk, userType, and the optional locationId. Response structure unchanged (read bare, or inside {success, message, data}; the file link from download_url or downloadUrlPath). The swagger path was written with a double slash (analysis-service//pythonReportController); the frontend uses a single slash.
A19: Consumption Analysis | B19: GET | C19: /item-ingredient-analysis-service/itemIngredientAnalysisController/categoryDropDown | D19: /analysis-service/itemIngredientAnalysisController/categoryDropDown | E19: Integrated | F19: 46303 | H19: Moved to analysis-service. Response is {success, data:[...]}; the name is read and the 'All Category' entry dropped (the screen adds its own).
A20: Consumption Analysis | B20: GET | C20: /item-ingredient-analysis-service/itemIngredientAnalysisController/srcTypeDropDown/{date}/{locationId} | D20: /analysis-service/itemIngredientAnalysisController/srcTypeDropDown/{period}/{location} | E20: Integrated | F20: 46303 | H20: Moved to analysis-service. Response is {success, data:[...]}; the name is read. The new path has no userType / userId (the old one did not either).
A21: Consumption Analysis | B21: GET | C21: /location-details-service/locationDetailsController/overallDropDown/{idx}/{date}/{userType}/{userId} | D21: /analysis-service/locationDetailsController/overallDropDown/{type}/{date}/{userType}/{userId} | E21: Integrated | F21: 46303 | H21: Moved to analysis-service. Response is {success, data:[...]} of the wide shared DTO; id/name (or locationId/locationName) are read. type 1-3 = the location type's category list (name only).
A22: Consumption Analysis | B22: GET | C22: /location-details-service/locationDetailsController/overallDropDown/0/{date}/{userType}/{userId} | D22: /analysis-service/locationDetailsController/overallDropDown/0/{date}/{userType}/{userId} | E22: Integrated | F22: 46303 | H22: Same endpoint as the row above with type 0 = every location (the filter's location list, and the names that fill the summary table).
A23: Consumption Analysis | B23: GET | C23: /location-details-service/locationDetailsController/dropDownByNameBased/{idx}/{category}/{date}/{userType}/{userId} | D23: /analysis-service/locationDetailsController/dropDownByNameBased/{type}/{typeName}/{date}/{userType}/{userId} | E23: Integrated | F23: 46303 | H23: Moved to analysis-service. Response is {success, data:[...]}; the category is URL-encoded.
A24: Consumption Analysis | B24: GET | C24: /location-summary-service/locationSummaryController/consumptionOverallSummary/{date}/{userType}/{userId} | D24: /analysis-service/locationSummaryController/consumptionOverallSummary/{period}/{userType}/{userId} | E24: Integrated | F24: 46303 | H24: Moved to analysis-service. Response is {success, data:[one row per location]}; locationId, locationName, itemCount, totalQty, convertedQty and totalAmount are read.
A25: Consumption Analysis | B25: POST | C25: /location-summary-service/locationSummaryController/consumptionByLocationByDate | D25: /analysis-service/locationSummaryController/consumptionByLocationByDate | E25: Integrated | F25: 46303 | G25: Yes | H25: TELL BACKEND TEAM: moved to analysis-service; the response is now {success, data:{summaryList, srcTypeList, perMandayList, srcTypeMasterList}} instead of responseContents / responseContents2 / responseContents3 / responseContents4. summaryList = the item rows, srcTypeList = the per-source-type chart, perMandayList = the per-manday chart; srcTypeMasterList is not used by the screen. Please confirm: (1) the item rows carry no unit price, so the frontend works it out as totalAmount / totalQty - is that right? (2) in perMandayList the per-manday figures are read from dynamicPerMandayMap (falling back to dynamicSrcTypeMap) with keys like '<srcType>_TotalQtyPerManday' / '<srcType>_ConvertedQtyPerManday' - which map and keys do they arrive in? The request is unchanged (locationId, periodStr, and category / srcType when set).
A26: Consumption Analysis | B26: GET | C26: /consolidated-python-report-service/pythonReportController/getConsumptionReport | D26: /analysis-service/pythonReportController/getConsumptionReport | E26: Integrated | F26: 46303 | G26: Yes | H26: TELL BACKEND TEAM: moved to analysis-service; the swagger gives no response structure for this Excel download (query period, userFk, userType as strings, optional locationId). The old call returned JSON with a download_url. The frontend now saves a file reply, shows the message of a JSON error, and opens a JSON file link (download_url / downloadUrlPath), so any of the three works - please confirm which it is. period is the reporting date as DD-MM-YYYY.
A27: Stock on Hand | B27: GET | C27: /location-details-service/locationDetailsController/overallDropDown/{idx}/{date}/{userType}/{userId} | D27: /analysis-service/locationDetailsController/overallDropDown/{type}/{date}/{userType}/{userId} | E27: Integrated | F27: 46303 | G27: Yes | H27: Moved to analysis-service. The swagger gave this path without its controller name; locationDetailsController is assumed (same parameters as Consumption Analysis). Response is {success, data:[...]}; type 1-3 = the location type's category list.
A28: Stock on Hand | B28: GET | C28: /location-details-service/locationDetailsController/overallDropDown/0/{date}/{userType}/{userId} | D28: /analysis-service/locationDetailsController/overallDropDown/0/{date}/{userType}/{userId} | E28: Integrated | F28: 46303 | G28: Yes | H28: Same endpoint as the row above with type 0 = every location (the picker's list and the names that fill the summary table). Controller name assumed - see the row above.
A29: Stock on Hand | B29: GET | C29: /location-details-service/locationDetailsController/dropDownByNameBased/{idx}/{category}/{date}/{userType}/{userId} | D29: /analysis-service/locationDetailsController/dropDownByNameBased/{type}/{typeName}/{date}/{userType}/{userId} | E29: Integrated | F29: 46303 | H29: Moved to analysis-service. Response is {success, data:[...]}; the category is URL-encoded.
A30: Stock on Hand | B30: POST | C30: /location-summary-service/locationSummaryController/sohAnalysisLst | D30: /analysis-service/locationSummaryController/sohAnalysisLst | E30: Integrated | F30: 46303 | G30: Yes | H30: TELL BACKEND TEAM: moved to analysis-service; response is now {success, data:{summary, sohList}} (was responseContents / responseContent). Items = sohList, the days-holding threshold = summary.stockGrtDays. userId is sent as a number. Still called once per location for the summary table because the bulk call does not tag rows with their location - please confirm sohList rows carry locationId when called without one.
A31: Stock on Hand | B31: GET | C31: /consolidated-python-report-service/pythonReportController/getSohAnalysis?period&userType&userFk | D31: /analysis-service/pythonReportController/getSohAnalysis | E31: Integrated | F31: 46303 | G31: Yes | H31: TELL BACKEND TEAM: moved to analysis-service; the swagger shows an empty response for this Excel download. The old call returned JSON with a download_url. The frontend now saves a file reply, shows the message of a JSON error, and opens a JSON file link, so any of the three works - please confirm which it is. period is YYYY-MM-DD; locationId optional.
A32: Stock on Hand | B32: GET | C32: /consolidated-python-report-service/pythonReportController/getSohAnalysis?period&locationId&userType&userFk | D32: /analysis-service/pythonReportController/getSohAnalysis | E32: Integrated | F32: 46303 | G32: Yes | H32: TELL BACKEND TEAM: moved to analysis-service; the swagger shows an empty response for this Excel download. The old call returned JSON with a download_url. The frontend now saves a file reply, shows the message of a JSON error, and opens a JSON file link, so any of the three works - please confirm which it is. period is YYYY-MM-DD; locationId optional.
A33: Data Tracker Report | B33: GET | C33: /consolidated-python-report-service/pythonReportController/lmsDataTrackerReport | D33: /analysis-service/pythonReportController/lmsDataTrackerReport?period=YYYY-MM-01 | E33: Integrated | F33: 46303 | G33: Yes | H33: TELL BACKEND TEAM: moved from consolidated-python-report-service to analysis-service. The new swagger lists period (required) and an optional locationId, and shows the response as an empty object ({}), so the shape is unconfirmed. The frontend assumes the same JSON as before (status, period, download_url, day_numbers, days, detail_sheet.data[]) - bare or inside {success, message, data} - and also accepts downloadUrlPath for the file link. It never sends locationId (the screen shows every location). Please confirm the response, ideally with a sample.
A34: Target PRJ | B34: GET | C34: /location-insight-service/locationInsightController/listOfPropertyTargetPrj/{date} | D34: /overallSummary-service/locationInsightController/listOfPropertyTargetPrj/{period} | E34: Integrated | F34: 46303 | H34: Service switched to overallSummary-service. Response is {success, message, data:[locations]}, each with its targetPrjList (prjId, controllPrjId, prjStatus, period, targetValue). The old response's totalRecords and sum are not in the new one; the screen never used them. A missing target stays empty (not 0). period is the reporting date as DD-MM-YYYY.
A35: Target PRJ | B35: POST | C35: /location-insight-service/locationInsightController/modifyPropertyTargetPrj | D35: /overallSummary-service/locationInsightController/modifyPropertyTargetPrj | E35: Integrated | F35: 46303 | G35: Yes | H35: TELL BACKEND TEAM: service switched to overallSummary-service; response is {success, message, data:'string'} and success:false is shown as the save error. The new request body has more fields than the old one (locationName, propertyValue, status per location; controllPrjId, prjStatus, period per target). The frontend sends back, for each changed target, exactly what the list returned with only targetValue changed, and only the changed targets of the one location being saved. period is the reporting date as DD-MM-YYYY (the swagger just says string). Please confirm this is what the backend expects.
A36: Productivity | B36: GET | C36: /location-insight-service/locationInsightController/listOfPropertyProductivity/{date} | D36: /overallSummary-service/locationInsightController/listOfPropertyProductivity/{period} | E36: Integrated | F36: 46303 | H36: Service switched to overallSummary-service. Response is {success, message, data:[rows]}, each row with locationId, locationName, propertyValue, status, period and productivity. The old response's totalRecords is not in the new one; the screen never used it. A missing productivity stays empty (not 0). period is the reporting date as DD-MM-YYYY.
A37: Productivity | B37: POST | C37: /location-insight-service/locationInsightController/modifyPropertyProductivity | D37: /overallSummary-service/locationInsightController/modifyPropertyProductivity | E37: Integrated | F37: 46303 | G37: Yes | H37: TELL BACKEND TEAM: service switched to overallSummary-service; response is {success, message, data:'string'} and success:false is shown as the save error. Each location in the new request has more fields than the old one (propertyValue, status, period next to locationId, locationName, productivity). The frontend sends back, for every changed location, exactly what the list returned with only productivity changed. The top-level period is the reporting date as DD-MM-YYYY (the swagger just says string). Please confirm this is what the backend expects.
A38: Report | B38: GET | C38: /consolidated-python-report-service/pythonReportController/{reportKey}?period=YYYY-MM | D38: /consolidated-python-report-service/pythonReportController/{reportKey}?period=YYYY-MM | E38: Integrated | F38: 46302 | G38: Yes | H38: TELL BACKEND TEAM: the new backend serves the same path (swagger: GET .../pythonReportController/stockReportConsolidated with a period query param; the last segment is the report the user picks, 35 reports - see the 'Report types' sheet). Only stockReportConsolidated's request was shown and no response sample was given, so please confirm that (1) the other 34 report methods keep the same name and period=YYYY-MM, and (2) the response still carries the file link as download_url - the frontend also accepts the new envelope's downloadUrlPath (top level or inside data), and shows message / error when there is no file.
A39: Category Analysis | B39: GET | C39: /category-analysis-service/categoryAnalysisController/overallDropDown/{idx}/{date}/{userType}/{userId} | D39: /item-analysis-summary-service/categoryAnalysisController/overallDropDown/{type}/{date}/{userType}/{userId} | E39: Integrated | F39: 46302 | H39: Service switched to item-analysis-summary-service. Response is {success, data:[...]} of the backend's wide shared DTO; id/name (or locationId/locationName) and startDay are read, and startDay is parsed to a number. type 1-3 = category list (name only).
A40: Category Analysis | B40: GET | C40: /category-analysis-service/categoryAnalysisController/overallDropDown/0/{date}/{userType}/{userId} | D40: /item-analysis-summary-service/categoryAnalysisController/overallDropDown/0/{date}/{userType}/{userId} | E40: Integrated | F40: 46302 | H40: Same endpoint as the row above with type 0 = every location (the picker's location search). Same response handling.
...

Sheet Report types
A1: Report screen - the 35 reports the user can pick (each is the last segment of the one endpoint)
A2: The new backend serves the same path; the last segment is the report the user picks. Only stockReportConsolidated was shown in the new swagger, so the other 34 follow the same pattern until the backend team confirms. If a report's endpoint changes, edit its 'New endpoint' cell and the frontend list. The report key is also the backend method name, so copy it exactly (including its own spellings).
A4: # | B4: Report (as shown to the user) | C4: Report key (path segment) | D4: Old endpoint | E4: New endpoint | F4: Same list in old and new?
A5: 1 | B5: Cash Movement - Consolidated | C5: cashMovementConsolidated | D5: /consolidated-python-report-service/pythonReportController/cashMovementConsolidated?period=YYYY-MM | E5: /consolidated-python-report-service/pythonReportController/cashMovementConsolidated?period=YYYY-MM (same pattern - to be confirmed) | F5: Yes
A6: 2 | B6: Accounting Details - Consolidated | C6: accountingDetails | D6: /consolidated-python-report-service/pythonReportController/accountingDetails?period=YYYY-MM | E6: /consolidated-python-report-service/pythonReportController/accountingDetails?period=YYYY-MM (same pattern - to be confirmed) | F6: Yes
A7: 3 | B7: Cash Entry - Consolidated | C7: cashEntry | D7: /consolidated-python-report-service/pythonReportController/cashEntry?period=YYYY-MM | E7: /consolidated-python-report-service/pythonReportController/cashEntry?period=YYYY-MM (same pattern - to be confirmed) | F7: Yes
A8: 4 | B8: Cash Movement Summary - Consolidated | C8: cashMovementSummaryConsolidated | D8: /consolidated-python-report-service/pythonReportController/cashMovementSummaryConsolidated?period=YYYY-MM | E8: /consolidated-python-report-service/pythonReportController/cashMovementSummaryConsolidated?period=YYYY-MM (same pattern - to be confirmed) | F8: Yes
A9: 5 | B9: Consumption By Category - Consolidated | C9: consumptionByCategoryConsolidated | D9: /consolidated-python-report-service/pythonReportController/consumptionByCategoryConsolidated?period=YYYY-MM | E9: /consolidated-python-report-service/pythonReportController/consumptionByCategoryConsolidated?period=YYYY-MM (same pattern - to be confirmed) | F9: Yes
A10: 6 | B10: Credit Journal - Consolidated | C10: creaditJournalConsolidated | D10: /consolidated-python-report-service/pythonReportController/creaditJournalConsolidated?period=YYYY-MM | E10: /consolidated-python-report-service/pythonReportController/creaditJournalConsolidated?period=YYYY-MM (same pattern - to be confirmed) | F10: Yes
A11: 7 | B11: CWH In Details - Consolidated | C11: cwhInDetailsConsolidated | D11: /consolidated-python-report-service/pythonReportController/cwhInDetailsConsolidated?period=YYYY-MM | E11: /consolidated-python-report-service/pythonReportController/cwhInDetailsConsolidated?period=YYYY-MM (same pattern - to be confirmed) | F11: Yes
A12: 8 | B12: CWH In Summary - Consolidated | C12: cwhInSummaryConsolidated | D12: /consolidated-python-report-service/pythonReportController/cwhInSummaryConsolidated?period=YYYY-MM | E12: /consolidated-python-report-service/pythonReportController/cwhInSummaryConsolidated?period=YYYY-MM (same pattern - to be confirmed) | F12: Yes
A13: 9 | B13: CWH Out Details - Consolidated | C13: cwhOutDetailsConsolidated | D13: /consolidated-python-report-service/pythonReportController/cwhOutDetailsConsolidated?period=YYYY-MM | E13: /consolidated-python-report-service/pythonReportController/cwhOutDetailsConsolidated?period=YYYY-MM (same pattern - to be confirmed) | F13: Yes
A14: 10 | B14: CWH Out Summary - Consolidated | C14: cwhOutSummaryConsolidated | D14: /consolidated-python-report-service/pythonReportController/cwhOutSummaryConsolidated?period=YYYY-MM | E14: /consolidated-python-report-service/pythonReportController/cwhOutSummaryConsolidated?period=YYYY-MM (same pattern - to be confirmed) | F14: Yes
A15: 11 | B15: Daily SRC Details - Consolidated | C15: dailySrcDetailsConsolidated | D15: /consolidated-python-report-service/pythonReportController/dailySrcDetailsConsolidated?period=YYYY-MM | E15: /consolidated-python-report-service/pythonReportController/dailySrcDetailsConsolidated?period=YYYY-MM (same pattern - to be confirmed) | F15: Yes
A16: 12 | B16: Daily SRC Summary (All SRC) - Consolidated | C16: dailySrcSummaryConsolidated | D16: /consolidated-python-report-service/pythonReportController/dailySrcSummaryConsolidated?period=YYYY-MM | E16: /consolidated-python-report-service/pythonReportController/dailySrcSummaryConsolidated?period=YYYY-MM (same pattern - to be confirmed) | F16: Yes
... A39: 35 | B39: Physical Stock Discrepancies - Consolidated | C39: physicalStockDiscrepancies | D39: /consolidated-python-report-service/pythonReportController/physicalStockDiscrepancies?period=YYYY-MM | E39: /consolidated-python-report-service/pythonReportController/physicalStockDiscrepancies?period=YYYY-MM (same pattern - to be confirmed) | F39: Yes

Sheet How to use
A1: ELMS Watch - new backend API tracker
A2: Purpose | B2: Shows which screens of the new frontend already use the new backend API, and which endpoints each one calls.
A3: Screen Status sheet | B3: One row per screen. The endpoint counts, 'New API added?' and 'Last updated' are calculated from the Endpoints sheet - do not type over them. 'Tour covers all options?' and Notes are typed by hand.
A4: Endpoints sheet | B4: One row per endpoint a screen calls. A call used two ways (e.g. with and without locationId) gets one row for each way, and a call a screen gets through a shared component (the location picker) is listed for that screen too, so the counts match the 'Old vs New APIs' sheet.
A5: Cells to edit | B5: On Endpoints: New endpoint, Status, Date integrated, Tell backend team? (Yes / blank), Notes. A new endpoint is a new row with the exact screen name from Screen Status. On Screen Status: 'Tour covers all options?' (Yes / No / n/a) and Notes.
